Time slot   0
	Loaded a process at input/proc/s4, PID: 1 PRIO: 4
Time slot   1
Time slot   2
	CPU 0: Dispatched process  1
	Loaded a process at input/proc/s3, PID: 2 PRIO: 3
Time slot   3
	Loaded a process at input/proc/m1, PID: 3 PRIO: 2
Time slot   4
	CPU 0: Put process  1 to run queue
	CPU 0: Dispatched process  1
Time slot   5
	Loaded a process at input/proc/s2, PID: 4 PRIO: 3
Time slot   6
	CPU 0: Put process  1 to run queue
	CPU 0: Dispatched process  3
Time slot   7
	Loaded a process at input/proc/m0, PID: 5 PRIO: 3
Time slot   8
	CPU 0: Put process  3 to run queue
	CPU 0: Dispatched process  4
	Loaded a process at input/proc/p1, PID: 6 PRIO: 2
Time slot   9
Time slot  10
	CPU 0: Put process  4 to run queue
	CPU 0: Dispatched process  4
	Loaded a process at input/proc/s0, PID: 7 PRIO: 1
Time slot  11
Time slot  12
	CPU 0: Put process  4 to run queue
	CPU 0: Dispatched process  4
Time slot  13
Time slot  14
	CPU 0: Put process  4 to run queue
	CPU 0: Dispatched process  4
Time slot  15
	Loaded a process at input/proc/s1, PID: 8 PRIO: 0
Time slot  16
	CPU 0: Put process  4 to run queue
	CPU 0: Dispatched process  4
Time slot  17
Time slot  18
	CPU 0: Put process  4 to run queue
	CPU 0: Dispatched process  4
Time slot  19
Time slot  20
	CPU 0: Processed  4 has finished
	CPU 0: Dispatched process  2
Time slot  21
Time slot  22
	CPU 0: Put process  2 to run queue
	CPU 0: Dispatched process  2
Time slot  23
Time slot  24
	CPU 0: Put process  2 to run queue
	CPU 0: Dispatched process  2
Time slot  25
Time slot  26
	CPU 0: Put process  2 to run queue
	CPU 0: Dispatched process  2
Time slot  27
Time slot  28
	CPU 0: Put process  2 to run queue
	CPU 0: Dispatched process  2
Time slot  29
Time slot  30
	CPU 0: Put process  2 to run queue
	CPU 0: Dispatched process  2
Time slot  31
	CPU 0: Processed  2 has finished
	CPU 0: Dispatched process  5
Time slot  32
Time slot  33
	CPU 0: Put process  5 to run queue
	CPU 0: Dispatched process  1
Time slot  34
Time slot  35
	CPU 0: Put process  1 to run queue
	CPU 0: Dispatched process  8
Time slot  36
Time slot  37
	CPU 0: Put process  8 to run queue
	CPU 0: Dispatched process  7
Time slot  38
Time slot  39
	CPU 0: Put process  7 to run queue
	CPU 0: Dispatched process  6
Time slot  40
Time slot  41
	CPU 0: Put process  6 to run queue
	CPU 0: Dispatched process  6
Time slot  42
Time slot  43
	CPU 0: Put process  6 to run queue
	CPU 0: Dispatched process  6
Time slot  44
Time slot  45
	CPU 0: Put process  6 to run queue
	CPU 0: Dispatched process  6
Time slot  46
Time slot  47
	CPU 0: Put process  6 to run queue
	CPU 0: Dispatched process  6
Time slot  48
Time slot  49
	CPU 0: Processed  6 has finished
	CPU 0: Dispatched process  3
Time slot  50
Time slot  51
	CPU 0: Put process  3 to run queue
	CPU 0: Dispatched process  5
Time slot  52
Time slot  53
	CPU 0: Put process  5 to run queue
	CPU 0: Dispatched process  1
Time slot  54
	CPU 0: Processed  1 has finished
	CPU 0: Dispatched process  8
Time slot  55
Time slot  56
	CPU 0: Put process  8 to run queue
	CPU 0: Dispatched process  7
Time slot  57
Time slot  58
	CPU 0: Put process  7 to run queue
	CPU 0: Dispatched process  3
Time slot  59
Time slot  60
	CPU 0: Put process  3 to run queue
	CPU 0: Dispatched process  5
Time slot  61
Time slot  62
	CPU 0: Put process  5 to run queue
	CPU 0: Dispatched process  8
Time slot  63
Time slot  64
	CPU 0: Put process  8 to run queue
	CPU 0: Dispatched process  7
Time slot  65
Time slot  66
	CPU 0: Put process  7 to run queue
	CPU 0: Dispatched process  3
Time slot  67
Time slot  68
	CPU 0: Processed  3 has finished
	CPU 0: Dispatched process  5
Time slot  69
	CPU 0: Processed  5 has finished
	CPU 0: Dispatched process  8
Time slot  70
	CPU 0: Processed  8 has finished
	CPU 0: Dispatched process  7
Time slot  71
Time slot  72
	CPU 0: Put process  7 to run queue
	CPU 0: Dispatched process  7
Time slot  73
Time slot  74
	CPU 0: Put process  7 to run queue
	CPU 0: Dispatched process  7
Time slot  75
Time slot  76
	CPU 0: Put process  7 to run queue
	CPU 0: Dispatched process  7
Time slot  77
Time slot  78
	CPU 0: Put process  7 to run queue
	CPU 0: Dispatched process  7
Time slot  79
	CPU 0: Processed  7 has finished
	CPU 0 stopped

MEMORY CONTENT: 
000: 00000-003ff - PID: 05 (idx 000, nxt: 001)
001: 00400-007ff - PID: 05 (idx 001, nxt: 009)
002: 00800-00bff - PID: 05 (idx 000, nxt: 003)
	00be8: 15
003: 00c00-00fff - PID: 05 (idx 001, nxt: -01)
009: 02400-027ff - PID: 05 (idx 002, nxt: 010)
010: 02800-02bff - PID: 05 (idx 003, nxt: 011)
011: 02c00-02fff - PID: 05 (idx 004, nxt: -01)
030: 07800-07bff - PID: 05 (idx 000, nxt: 031)
	07814: 66
031: 07c00-07fff - PID: 05 (idx 001, nxt: -01)
