Time slot   0
	Loaded a process at input/proc/s4, PID: 1 PRIO: 4
Time slot   1
	CPU 0: Dispatched process  1
Time slot   2
	Loaded a process at input/proc/s3, PID: 2 PRIO: 3
Time slot   3
	CPU 0: Put process  1 to run queue
	CPU 0: Dispatched process  2
	Loaded a process at input/proc/m1, PID: 3 PRIO: 2
Time slot   4
	CPU 1: Dispatched process  1
Time slot   5
	CPU 0: Put process  2 to run queue
	CPU 0: Dispatched process  3
	Loaded a process at input/proc/s2, PID: 4 PRIO: 3
	CPU 1: Put process  1 to run queue
	CPU 1: Dispatched process  4
Time slot   6
Time slot   7
	CPU 0: Put process  3 to run queue
	CPU 0: Dispatched process  2
	Loaded a process at input/proc/m0, PID: 5 PRIO: 3
	CPU 1: Put process  4 to run queue
	CPU 1: Dispatched process  1
Time slot   8
	Loaded a process at input/proc/p1, PID: 6 PRIO: 2
Time slot   9
	CPU 0: Put process  2 to run queue
	CPU 0: Dispatched process  6
	CPU 1: Put process  1 to run queue
	CPU 1: Dispatched process  3
Time slot  10
	Loaded a process at input/proc/s0, PID: 7 PRIO: 1
Time slot  11
	CPU 0: Put process  6 to run queue
	CPU 0: Dispatched process  4
	CPU 1: Put process  3 to run queue
	CPU 1: Dispatched process  2
Time slot  12
Time slot  13
	CPU 0: Put process  4 to run queue
	CPU 0: Dispatched process  4
	CPU 1: Put process  2 to run queue
	CPU 1: Dispatched process  2
Time slot  14
Time slot  15
	CPU 0: Put process  4 to run queue
	CPU 0: Dispatched process  4
	CPU 1: Put process  2 to run queue
	CPU 1: Dispatched process  2
Time slot  16
	Loaded a process at input/proc/s1, PID: 8 PRIO: 0
Time slot  17
	CPU 0: Put process  4 to run queue
	CPU 0: Dispatched process  4
	CPU 1: Put process  2 to run queue
	CPU 1: Dispatched process  2
Time slot  18
	CPU 1: Processed  2 has finished
	CPU 1: Dispatched process  5
Time slot  19
	CPU 0: Put process  4 to run queue
	CPU 0: Dispatched process  1
Time slot  20
	CPU 0: Processed  1 has finished
	CPU 0: Dispatched process  8
	CPU 1: Put process  5 to run queue
	CPU 1: Dispatched process  7
Time slot  21
Time slot  22
	CPU 0: Put process  8 to run queue
	CPU 0: Dispatched process  3
	CPU 1: Put process  7 to run queue
	CPU 1: Dispatched process  6
Time slot  23
Time slot  24
	CPU 0: Put process  3 to run queue
	CPU 0: Dispatched process  4
	CPU 1: Put process  6 to run queue
	CPU 1: Dispatched process  5
Time slot  25
Time slot  26
	CPU 0: Processed  4 has finished
	CPU 0: Dispatched process  8
Time slot  27
	CPU 1: Put process  5 to run queue
	CPU 1: Dispatched process  7
Time slot  28
	CPU 0: Put process  8 to run queue
	CPU 0: Dispatched process  6
Time slot  29
	CPU 1: Put process  7 to run queue
	CPU 1: Dispatched process  3
Time slot  30
	CPU 0: Put process  6 to run queue
	CPU 0: Dispatched process  5
	CPU 1: Processed  3 has finished
	CPU 1: Dispatched process  8
Time slot  31
Time slot  32
	CPU 0: Put process  5 to run queue
	CPU 0: Dispatched process  7
	CPU 1: Put process  8 to run queue
	CPU 1: Dispatched process  6
Time slot  33
Time slot  34
	CPU 0: Put process  7 to run queue
	CPU 0: Dispatched process  5
	CPU 1: Put process  6 to run queue
	CPU 1: Dispatched process  8
Time slot  35
	CPU 0: Processed  5 has finished
	CPU 0: Dispatched process  7
	CPU 1: Processed  8 has finished
	CPU 1: Dispatched process  6
Time slot  36
Time slot  37
	CPU 0: Put process  7 to run queue
	CPU 0 stopped
Time slot  38
	CPU 1: Processed  6 has finished
	CPU 1: Dispatched process  7
Time slot  39
Time slot  40
	CPU 1: Put process  7 to run queue
	CPU 1: Dispatched process  7
Time slot  41
Time slot  42
	CPU 1: Put process  7 to run queue
	CPU 1: Dispatched process  7
Time slot  43
Time slot  44
	CPU 1: Put process  7 to run queue
	CPU 1: Dispatched process  7
Time slot  45
	CPU 1: Processed  7 has finished
	CPU 1 stopped

MEMORY CONTENT: 
000: 00000-003ff - PID: 05 (idx 000, nxt: 001)
	003e8: 15
001: 00400-007ff - PID: 05 (idx 001, nxt: -01)
002: 00800-00bff - PID: 05 (idx 000, nxt: 003)
003: 00c00-00fff - PID: 05 (idx 001, nxt: 004)
004: 01000-013ff - PID: 05 (idx 002, nxt: 005)
005: 01400-017ff - PID: 05 (idx 003, nxt: 006)
006: 01800-01bff - PID: 05 (idx 004, nxt: -01)
018: 04800-04bff - PID: 05 (idx 000, nxt: 019)
	04814: 66
019: 04c00-04fff - PID: 05 (idx 001, nxt: -01)
